Workbook

Sheet Res.
B3: Estoque de Vinhos
B6: TINTO
B8: Pais | N8: Estoque
B9: FRANÇA | N9: =+'T. Fr'!K1045+'T.Fr. B.'!K843+'T.Fr.R.'!K497 -> 2434
B11: PORTUGAL | N11: =+'T. Pt'!K311 -> 273
B13: ESPANHA | N13: =+'T. Es'!K555 -> 510
B15: ITÁLIA | N15: =+'T. It'!K993 -> 796
B17: CHILE | N17: =+#REF! -> #REF!
B19: ARGENTINA | N19: =+#REF! -> #REF!
B21: ESTADOS UNIDOS DA AMÉRICA | N21: =+'T. US'!K643 -> 603
B23: AUSTRÁLIA | N23: =+'T. Aust'!K199 -> 190
B25: NOVA ZELÂNDIA | N25: =+#REF! -> #REF!
B27: ÁFRICA DO SUL | N27: =+#REF! -> #REF!
B29: ALEMANHA | N29: =+#REF! -> #REF!
B31: BRASIL + OUTROS | N31: =+#REF!+#REF! -> #REF!
B33: TOTAL DE VINHOS TINTOS | N33: =SUM(N9:N32) -> #REF!
B36: BRANCO
B38: Pais | N38: Estoque
B39: FRANÇA | N39: =+'B. Fr'!K31+'B.Fr.B.'!K427+'B.Fr.R.'!K131 -> 355
B41: PORTUGAL | N41: =+'B. Pt'!K113 -> 119
B43: ESPANHA | N43: =+'B. Es'!K35 -> 18
B45: ITÁLIA | N45: =+'B. It'!K43 -> 26
B47: CHILE | N47: =+#REF! -> #REF!
B49: ARGENTINA | N49: =+#REF! -> #REF!
B51: ESTADOS UNIDOS DA AMÉRICA | N51: =+'B. US'!K123 -> 74
B53: AUSTRÁLIA | N53: =+#REF! -> #REF!
B55: NOVA ZELÂNDIA | N55: =+#REF! -> #REF!
B57: ÁFRICA DO SUL | N57: =+#REF! -> #REF!
B59: ALEMANHA | N59: =+#REF! -> #REF!
B61: BRASIL + OUTROS | N61: =+#REF!+#REF! -> #REF!
B63: TOTAL DE VINHOS BRANCOS | N63: =SUM(N39:N62) -> #REF!
B65: TOTAL DE VINHOS DOCES | N65: =+#REF!+#REF!+#REF!+#REF!+#REF!+#REF!+#REF! -> #REF!
B67: TOTAL DE CHAMPAGNE | N67: =+#REF! -> #REF!
B69: TOTAL DE FORTIFICADOS | N69: =+#REF!+#REF!+#REF! -> #REF!
B71: TOTAL DE VINHOS TINTOS, VINHOS BRANCOS, FORTICADOS E CHAMPAGNE | N71: =+N33+N63+N65+N67+N69 -> #REF! | O71: =-N71+8256 -> #REF!
O74: =-N71+8256 -> #REF!

Sheet T. Fr
C3: ADEGA RICARDO SENA
C6: VINHOS DA FRANÇA
B7: TINTO
B9: Vinho | G9: Safra | H9: R.P. | I9: W.S. | J9: Beber | K9: Estoque
J10: R.P.
B11: BORDEAUX
B13: MÉDOC - PAUILLAC
B15: Latour | G15: 1955 | H15: 94 | J15: 00 - 20 | K15: 1
B17: Latour | G17: 1970 | H17: 89 | K17: 1
B19: Latour - Magnum | G19: 1970 | H19: 89 | K19: 1
B21: Latour | G21: 1982 | H21: 100 | I21: 98 | J21: 12 - 45 | K21: 2
B23: Latour | G23: 1989 | H23: 89 | J23: 00 - 20 | K23: 1
B25: Latour | G25: 1990 | H25: 95+ | I25: 100 | J25: 16 - 35 | K25: 5
B27: Latour - Magnum | G27: 1990 | H27: 95+ | I27: 100 | J27: 16 - 35 | K27: 1
B29: Latour | G29: 1994 | H29: 94 | I29: 91 | J29: 14 - 34 | K29: 1
B31: Latour | G31: 1995 | H31: 96 | I31: 94 | J31: 12 - 50 | K31: 5
B33: Latour - Magnum | G33: 1995 | H33: 96 | I33: 94 | J33: 12 - 50 | K33: 1
B35: Latour | G35: 1996 | H35: 95+ | I35: 96 | J35: 25 - 65 | K35: 5
B37: Latour - Magnum | G37: 1996 | H37: 95+ | I37: 96 | J37: 25 - 65 | K37: 1
B39: Latour | G39: 1998 | H39: 90 | I39: 90 | J39: 09 - 30 | K39: 2
B41: Latour | G41: 1999 | H41: 94 | I41: 93 | J41: 15 - 39 | K41: 2
B43: Latour | G43: 2001 | H43: 95 | I43: 95 | J43: 07 - 25 | K43: 3
B45: Latour | G45: 2002 | H45: 96 | I45: 96 | J45: 12 - 45 | K45: 2
B47: Latour | G47: 2003 | H47: 100 | I47: 98 | J47: 14 - 34 | K47: 4
B49: Latour - Magnum | G49: 2011 | H49: 93 - 95 | J49: 16 - 36 | K49: 1
B51: Lafite Rothschild | G51: 1953 | H51: 100 | K51: 1
B53: Lafite Rothschild | G53: 1955 | K53: 1
B55: Lafite Rothschild | G55: 1966 | H55: 84 | K55: 1
B57: Lafite Rothschild | G57: 1976 | H57: 93 | J57: 96 - 05 | K57: 2
B59: Lafite Rothschild | G59: 1979 | H59: 87 | J59: 97 - 12 | K59: 1
B61: Lafite Rothschild | G61: 1986 | H61: 95+ | I61: 94 | J61: 16 - 46 | K61: 4
B63: Lafite Rothschild | G63: 1989 | H63: 90 | J63: 06 - 25 | K63: 3
B65: Lafite Rothschild | G65: 1990 | H65: 96 | I65: 95 | J65: 14 - 44 | K65: 5
B67: MÉDOC - PAUILLAC (continuação)
B69: Lafite Rothschild | G69: 1995 | H69: 95 | I69: 96 | J69: 08 - 28 | K69: 3
B71: Lafite Rothschild - Magnum | G71: 1995 | H71: 95 | I71: 96 | J71: 08 - 28 | K71: 1
B73: Lafite Rothschild | G73: 1996 | H73: 98 | I73: 95 | J73: 20 - 50 | K73: 4
B75: Lafite Rothschild | G75: 1998 | H75: 96 | I75: 95 | J75: 18 - 38 | K75: 5
B77: Lafite Rothschild - Magnum | G77: 1998 | H77: 96 | I77: 95 | J77: 18 - 38 | K77: 1
B79: Lafite Rothschild | G79: 1999 | H79: 93 | I79: 95 | J79: 09 - 39 | K79: 2
...

Sheet T.Fr. B.
C3: ADEGA RICARDO SENA
C6: VINHOS DA FRANÇA
B7: TINTO
B9: Vinho | G9: Safra | H9: R.P. | I9: W.S. | J9: C.C. | K9: Estoque
B11: BOURGOGNE
B13: DRC - La Tâche - GC | G13: 1973 | K13: 1
B15: DRC - La Tâche - GC | G15: 1983 | H15: 92 | J15: 18.5 | K15: 1
B17: DRC - La Tâche - GC | G17: 1989 | H17: 89 | J17: 20 | K17: 1
B19: DRC - La Tâche - GC | G19: 1995 | H19: 95 | I19: 95 | J19: 18.5 | K19: 1
B21: DRC - La Tâche - GC | G21: 1996 | H21: 94 - 97 | I21: 96 | J21: 19.5 | K21: 1
B23: DRC - La Tâche - GC | G23: 1998 | J23: 18.5 | K23: 1
B25: DRC - La Tâche - GC | G25: 2006 | H25: 94 | I25: 97 | J25: 19 | K25: 1
B27: DRC - La Tâche - GC | G27: 2007 | H27: 93 | I27: 95 | J27: 19 | K27: 2
B29: DRC - La Tâche - GC | G29: 2011 | H29: 95 | K29: 1
B31: DRC - Richebourg - GC | G31: 1969 | H31: 87 | K31: 1
B33: DRC - Richebourg - GC | G33: 1985 | H33: 96 | I33: 100 | J33: 18 | K33: 1
B35: DRC - Richebourg - GC | G35: 1990 | H35: 95 | K35: 1
B37: DRC - Richebourg - GC | G37: 1991 | H37: 94 | J37: 18 | K37: 1
B39: DRC - Richebourg - GC | G39: 1993 | H39: 91 | J39: 17.5 | K39: 1
B41: DRC - Richebourg - GC | G41: 1995 | H41: 90+ | I41: 98 | K41: 2
B43: DRC - Richebourg - GC | G43: 1996 | H43: 96 | K43: 1
B45: DRC - Richebourg - GC | G45: 1997 | H45: 93 | J45: 18 | K45: 2
B47: DRC - Richebourg - GC | G47: 2003 | H47: 97 | K47: 2
B49: DRC - Richebourg - GC | G49: 2004 | I49: 94 | K49: 1
B51: DRC - Richebourg - GC | G51: 2006 | H51: 93 | I51: 95 | J51: 18 | K51: 2
B53: DRC - Richebourg - GC | G53: 2007 | H53: 94 | I53: 97 | J53: 17.5 | K53: 2
B55: DRC - Romanée-St-Vivant - GC | G55: 1988 | H55: 90 | J55: 19 | K55: 1
B57: DRC - Romanée-St-Vivant - GC | G57: 1990 | H57: 95 | J57: 19.5 | K57: 2
B59: DRC - Romanée-St-Vivant - GC | G59: 1996 | H59: 94 | I59: 95 | J59: 17 | K59: 1
B61: DRC - Romanée-St-Vivant - GC | G61: 2000 | J61: 17.5 | K61: 1
B63: DRC - Romanée-St-Vivant - GC | G63: 2002 | H63: 95 | I63: 95 | J63: 19 | K63: 1
B65: DRC - Romanée-St-Vivant - GC | G65: 2005 | H65: 96 - 97 | I65: 95 | K65: 1
B67: BOURGOGNE ( continuação )
B69: DRC - Romanée-St-Vivant - GC | G69: 2006 | H69: 95 | I69: 95 | J69: 17.5 | K69: 1
B71: DRC - Romanée-St-Vivant - GC | G71: 2007 | H71: 93 | I71: 94 | J71: 18.5 | K71: 1
B73: DRC - Romanée-St-Vivant - GC | G73: 2008 | H73: 94 | I73: 94 | J73: 18.5 | K73: 2
B75: DRC - Grands Échézeaux - GC | G75: 1993 | H75: 90 | J75: 17 | K75: 1
B77: DRC - Grands Échézeaux - GC | G77: 1995 | H77: 92 | I77: 93 | K77: 2
B79: DRC - Grands Échézeaux - GC - Magnum | G79: 2004 | K79: 1
B81: DRC - Grands Échézeaux - GC | G81: 2005 | H81: 95 - 96 | I81: 95 | K81: 2
...

Sheet T.Fr.R.
C3: ADEGA RICARDO SENA
C6: VINHOS DA FRANÇA
B7: TINTO
B9: Vinho | G9: Safra | H9: R.P. | I9: W.S. | J9: Beber | K9: Estoque
J10: R.P.
B11: RHÔNE
B13: CÔTE ROTIE
B15: E Guigal - La Mouline | G15: 1982 | H15: 99 | I15: 87 | J15: 95 - 08 | K15: 1
B17: E Guigal - La Mouline | G17: 1985 | H17: 100 | I17: 97 | J17: 96 - 12 | K17: 1
B19: E Guigal - La Mouline | G19: 1988 | H19: 100 | I19: 95 | J19: 99 - 15 | K19: 2
B21: E Guigal - La Mouline | G21: 1990 | H21: 99 | I21: 98 | J21: 97 - 18 | K21: 2
B23: E Guigal - La Mouline | G23: 1991 | H23: 100 | I23: 92 | J23: 96 - 12 | K23: 2
B25: E Guigal - La Mouline | G25: 1995 | H25: 99 | I25: 95 | J25: 99 - 19 | K25: 2
B27: E Guigal - La Mouline | G27: 1996 | H27: 93 | I27: 92 | J27: 01 - 13 | K27: 1
B29: E Guigal - La Mouline | G29: 1997 | H29: 96 | I29: 97 | J29: 02 - 15 | K29: 2
B31: E Guigal - La Mouline | G31: 1998 | H31: 97 | I31: 92 | J31: 04 - 22 | K31: 2
B33: E Guigal - La Mouline | G33: 1999 | H33: 100 | I33: 99 | K33: 4
B35: E Guigal - La Mouline | G35: 2001 | H35: 95+ | I35: 96 | J35: 16 - 26 | K35: 3
B37: E Guigal - La Mouline | G37: 2003 | H37: 100 | I37: 99 | K37: 4
B39: E Guigal - La Mouline | G39: 2004 | H39: 95 | J39: 14 - 29 | K39: 2
B41: E Guigal - La Mouline | G41: 2005 | H41: 100 | I41: 99 | J41: 14 - 44 | K41: 4
B43: E Guigal - La Mouline | G43: 2006 | H43: 95 | J43: 14 - 24 | K43: 2
B45: E Guigal - La Mouline | G45: 2007 | H45: 96+ | I45: 96 | J45: 17 - 32 | K45: 3
B47: E Guigal - La Mouline | G47: 2009 | H47: 100 | J47: 17 - 47 | K47: 2
B49: E Guigal - La Landonne | G49: 1983 | H49: 98 | I49: 92 | J49: 01 - 25 | K49: 1
B51: E Guigal - La Landonne | G51: 1985 | H51: 100 | I51: 100 | J51: 00 - 25 | K51: 2
B53: E Guigal - La Landonne | G53: 1990 | H53: 100 | I53: 97 | J53: 04 - 42 | K53: 4
B55: E Guigal - La Landonne | G55: 1991 | H55: 99 | I55: 95 | J55: 00 - 30 | K55: 2
B57: E Guigal - La Landonne | G57: 1995 | H57: 99+ | I57: 94 | J57: 99 - 19 | K57: 1
B59: E Guigal - La Landonne | G59: 1997 | H59: 98 | I59: 97 | J59: 03 - 22 | K59: 1
B61: E Guigal - La Landonne | G61: 1998 | H61: 100 | I61: 95 | J61: 07 - 25 | K61: 4
B63: E Guigal - La Landonne | G63: 1999 | H63: 100 | I63: 98 | J63: 15 - 30 | K63: 3
B65: E Guigal - La Landonne | G65: 2003 | H65: 100 | I65: 98 | J65: 15 - 40 | K65: 4
B67: CÔTE ROTIE (continuação )
B69: E Guigal - La Landonne | G69: 2004 | H69: 94 | J69: 15 - 25 | K69: 1
B71: E Guigal - La Landonne | G71: 2005 | H71: 100 | I71: 98 | J71: 20 - 55 | K71: 5
B73: E Guigal - La Landonne | G73: 2006 | H73: 96+ | I73: 97 | J73: 19 - 46 | K73: 3
B75: E Guigal - La Landonne | G75: 2007 | H75: 97 | I75: 97 | J75: 15 - 42 | K75: 3
B77: E Guigal - La Landonne | G77: 2013 | H77: 95+ | J77: 25 - 45 | K77: 1
B79: E Guigal - La Turque | G79: 1985 | H79: 100 | I79: 95 | J79: 96 - 12 | K79: 1
...

Sheet B. Fr
C3: ADEGA RICARDO SENA
D6: VINHOS DA FRANÇA
B7: BRANCO
B9: Vinho | G9: Safra | H9: R.P. | I9: W.S. | J9: Beber | K9: Estoque
J10: R.P.
B11: BORDEAUX
B13: Smith Haut Lafitte - Pessac Leognan | G13: 2003 | H13: 93 | J13: - 16 | K13: 1
B15: Domaine de Chevalier - Pessac Leognan | G15: 2004 | H15: 94 | J15: - 35 | K15: 1
B17: Domaine de Chevalier - Pessac Leognan | G17: 2006 | H17: 92 | I17: 91 | J17: 11 - 31 | K17: 7
B19: Monbousquet | G19: 2008 | H19: 89 | K19: 1
B21: Pape Clément - Pessac Leognan | G21: 2006 | H21: 98 | I21: 94 | K21: 2
B23: Pape Clément - Pessac Leognan | G23: 2009 | H23: 100 | I23: 93 | K23: 1
B25: Chateau Valoux - Pessac Leognan | G25: 2009 | K25: 1
B27: Chateau Laville Haut-Brion - Pessac Leognan - Magnum | G27: 2005 | H27: 94+ | K27: 2
B29: Blanc de Valandraud N 1 | G29: 2005 | K29: 1
B31: BORDEAUX ( total ) | K31: 17 | L31: =SUM(L13:L30) -> 0
L35: =SUM(K13:K30)-L31 -> 17

Sheet B.Fr.B.
C3: ADEGA RICARDO SENA
D6: VINHOS DA FRANÇA
B7: BRANCO
B9: Vinho | G9: Safra | H9: R.P. | I9: W.S. | J9: C.C | K9: Estoque
B11: BOURGOGNE
B13: Romanée Conti - Montrachet. | G13: 1994 | H13: 93 | I13: 95 | K13: 1
B15: Ramonet - Montrachet | G15: 1983 | H15: 100 | I15: 97 | K15: 1
B17: Ramonet - Montrachet | G17: 1986 | H17: 97 | K17: 1
B19: Ramonet - Montrachet | G19: 1990 | H19: 93 | I19: 98 | K19: 1
B21: Ramonet - Montrachet | G21: 1994 | H21: 90 | I21: 96 | K21: 1
B23: Ramonet - Montrachet - Magnum | G23: 1994 | H23: 90 | I23: 96 | K23: 1
B25: Ramonet - Batard Montrachet | G25: 1992 | H25: 93 | I25: 94 | K25: 1
B27: Ramonet - Batard Montrachet | G27: 2003 | K27: 1
B29: Ramonet - Batard Montrachet | G29: 2006 | I29: 96 | K29: 1
B31: Ramonet - Bienvenue Batard Montrachet | G31: 1982 | I31: 93 | K31: 1
B33: Ramonet - Bienvenue Batard Montrachet | G33: 1988 | I33: 95 | K33: 2
B35: Ramonet - Bienvenue Batard Montrachet | G35: 1990 | H35: 89 | I35: 94 | J35: 18.5 | K35: 1
B37: Ramonet - Bienvenue Batard Montrachet | G37: 2003 | I37: 92 | K37: 1
B39: Coche-Dury - Corton - Charlemagne - G. C. | G39: 1997 | H39: 91 - 93 | I39: 92 | K39: 1
B41: Coche-Dury - Corton - Charlemagne - G. C. | G41: 2006 | H41: 95 - 96 | K41: 1
B43: Coche-Dury - Corton - Charlemagne - G. C. | G43: 2008 | H43: 100 | K43: 2
B45: Coche-Dury - Meursault | G45: 1990 | K45: 1
B47: Coche-Dury - Meursault - Les Rougeots | G47: 1999 | H47: 90 - 91 | K47: 1
B49: Coche-Dury - Meursault - Genevrieres | G49: 2005 | H49: 96 | K49: 1
B51: Leflaive - Batard -Montrachet G. C. | G51: 1990 | H51: 94 | I51: 95 | K51: 1
B53: Leflaive - Batard -Montrachet G. C. | G53: 1992 | H53: 97 | J53: 16 | K53: 2
B55: Leflaive - Batard -Montrachet G. C. | G55: 1999 | H55: 94 | K55: 1
B57: Leflaive - Batard -Montrachet G. C. | G57: 2000 | H57: 90 - 92 | J57: 18 | K57: 1
B59: Leflaive - Batard -Montrachet G. C. | G59: 2005 | K59: 1
B61: Leflaive - Batard -Montrachet G. C. | G61: 2009 | H61: 96 | J61: 17.5 | K61: 2
B63: Leflaive - Batard -Montrachet G. C. | G63: 2011 | H63: 95 | K63: 1
B65: Leflaive - Chevalier -Montrachet G. C. - Magnum | G65: 1997 | H65: 93 | K65: 1
B67: BOURGOGNE (continuação)
B69: Leflaive - Chevalier -Montrachet G. C. | G69: 2009 | H69: 94 | K69: 1
B71: Leflaive - Bienvenues - Batard -Montrachet G. C. | G71: 2006 | K71: 1
B73: Leflaive - Bienvenues - Batard -Montrachet G. C. | G73: 2010 | H73: 97 | K73: 2
B75: Leflaive - Bienvenues - Batard -Montrachet G. C. | G75: 2013 | H75: 93 | K75: 1
B77: Leflaive - Puligny -Montrachet - Les Pucelles | G77: 1983 | K77: 1
B79: Leflaive - Puligny -Montrachet - Les Pucelles | G79: 1988 | K79: 1
B81: Leflaive - Puligny -Montrachet - Les Pucelles - P. C. | G81: 1992 | H81: 96 | K81: 1
...

Sheet B.Fr.R.
C3: ADEGA RICARDO SENA
D6: VINHOS DA FRANÇA
B7: BRANCO
B9: Vinho | G9: Safra | H9: R.P. | I9: W.S. | J9: Beber | K9: Estoque
J10: R.P.
B11: RHÔNE
B13: M. Chapoutier - De L`Orée | G13: 1994 | H13: 99 | J13: 95 - 45 | K13: 1
B15: M. Chapoutier - De L`Orée - Magnum | G15: 1996 | H15: 99 | I15: 94 | K15: 1
B17: M. Chapoutier - De L`Orée | G17: 1997 | H17: 98 - 100 | J17: 03 - 50 | K17: 2
B19: M. Chapoutier - De L`Orée - Magnum | G19: 1998 | H19: 99 | K19: 1
B21: M. Chapoutier - De L`Orée | G21: 2000 | H21: 100 | J21: 03 - 53 | K21: 2
B23: M. Chapoutier - De L`Orée | G23: 2004 | H23: 99 | I23: 96 | K23: 2
B25: M. Chapoutier - De L`Orée - Magnum | G25: 2004 | H25: 99 | I25: 96 | K25: 1
B27: M. Chapoutier - De L`Orée | G27: 2010 | H27: 100 | K27: 1
B29: M. Chapoutier - Le Méal | G29: 2005 | H29: 96 | I29: 97 | J29: 12 - 37 | K29: 1
B31: M. Chapoutier - Le Méal | G31: 2006 | H31: 99 | I31: 97 | J31: 09 - 39 | K31: 2
B33: M. Chapoutier - Le Méal | G33: 2009 | H33: 98 | I33: 98 | J33: 11 - 41 | K33: 1
B35: M. Chapoutier - L`Ermite | G35: 1999 | H35: 100 | I35: 92 | J35: 12 - 50 | K35: 1
B37: M. Chapoutier - L`Ermite | G37: 2001 | H37: 95 - 98 | I37: 95 | J37: 08 - 30 | K37: 1
B39: M. Chapoutier - L`Ermite | G39: 2011 | H39: 100 | K39: 2
B41: E. Guigal - Ex voto - Ermitage | G41: 2003 | H41: 96+ | I41: 96 | J41: 04 - 54 | K41: 1
B43: E. Guigal - Ex voto - Ermitage | G43: 2009 | H43: 94 - 97 | I43: 97 | J43: 11 - 61 | K43: 1
B45: Jean Louis Chave - Hermitage | G45: 2003 | H45: 99 | I45: 97 | K45: 1
B47: Jean Louis Chave - Hermitage | G47: 2004 | H47: 95 | K47: 1
B49: Jean Louis Chave - Hermitage | G49: 2005 | H49: 96 | I49: 98 | K49: 1
B51: Jean Louis Chave - Hermitage | G51: 2006 | H51: 97 | I51: 99 | J51: 09 - 39 | K51: 2
B53: Jean Louis Chave - Hermitage | G53: 2009 | H53: 99 | I53: 98 | J53: 11 - 61 | K53: 1
B55: Jean Louis Chave - Hermitage | G55: 2012 | H55: 96 | K55: 1
B57: André Perret Condrieu Chéry | G57: 2022 | H57: 96 | K57: 1
B59: RHÔNE ( total ) | K59: 29 | L59: =+K59 -> 29
B61: VAL DU LOIRE
B63: Vouvray - Le Haut Lieu | G63: 1989 | H63: 96 | J63: 15 - 45 | K63: 3
B65: Vouvray - Le Mont | G65: 1996 | K65: 2
B67: VAL DU LOIRE (continuação)
B69: Vouvray - Clos du Bourg | G69: 2009 | H69: 91 | K69: 2
B71: Nicolas Joly - Savennières - Coulée de Serrant | G71: 2005 | H71: 86 | I71: 92 | K71: 1
B73: Nicolas Joly - Savennières - Coulée de Serrant | G73: 2006 | H73: 86 | I73: 90 | K73: 4
B75: Didier Dagueneau - Blanc Fumé De Pouilly | G75: 2009 | H75: 91 - 92+ | J75: 13 - 18 | K75: 1
B77: Marc Brédif - Vouvray -Classic | G77: 2017 | K77: 1
B79: Saumur Champigny - Clos Rougeard - Brézé - Não tinha espaço na adega de branco | G79: 2018 | K79: 2
...

Sheet T. It
C3: ADEGA RICARDO SENA
D6: VINHOS DA ITÁLIA
B7: TINTO
B9: Vinho | G9: Safra | H9: R.P. | I9: W.S. | J9: Beber | K9: Estoque
J10: R.P.
B11: PIEMONTE
B13: BAROLO
B15: Giacomo Conterno - Riserva Monfortino | G15: 1941 | K15: 1
B17: Giacomo Conterno - Riserva Monfortino | G17: 1945 | K17: 1
B19: Giacomo Conterno - Riserva Monfortino | G19: 1970 | H19: 90 | K19: 1
B21: Giacomo Conterno - Riserva Monfortino | G21: 1974 | H21: 95 | K21: 1
B23: Giacomo Conterno - Riserva Monfortino | G23: 1988 | H23: 94 | K23: 1
B25: Giacomo Conterno - Riserva Monfortino | G25: 1990 | H25: 98 | J25: 20 - 50 | K25: 3
B27: Giacomo Conterno - Riserva Monfortino | G27: 1996 | H27: 96 | I27: 97 | J27: 12 - 32 | K27: 3
B29: Giacomo Conterno - Riserva Monfortino | G29: 1997 | H29: 98 | I29: 96 | J29: 05 - 30 | K29: 2
B31: Giacomo Conterno - Riserva Monfortino | G31: 1998 | H31: 97 | I31: 94 | J31: 12 - 23 | K31: 1
B33: Giacomo Conterno - Riserva Monfortino | G33: 1999 | H33: 98 | J33: 14 - 39 | K33: 1
B35: Giacomo Conterno - Riserva Monfortino | G35: 2000 | H35: 97 | I35: 96 | J35: 20 - 40 | K35: 3
B37: Giacomo Conterno - Riserva Monfortino | G37: 2001 | H37: 98 | I37: 95 | J37: 21 - 41 | K37: 4
B39: Giacomo Conterno - Riserva Monfortino | G39: 2002 | H39: 98 | I39: 98 | J39: 27 - 52 | K39: 6
B41: Giacomo Conterno - Riserva Monfortino | G41: 2004 | H41: 100 | J41: 19 - 44 | K41: 3
B43: Giacomo Conterno - Cascina Francia | G43: 1990 | H43: 97 | J43: 10 - 30 | K43: 4
B45: Giacomo Conterno - Cascina Francia | G45: 1999 | H45: 94 | J45: 09 - 29 | K45: 2
B47: Giacomo Conterno - Cascina Francia | G47: 2001 | H47: 94+ | I47: 91 | J47: 15 - 31 | K47: 1
B49: Giacomo Conterno - Cascina Francia | G49: 2005 | H49: 95+ | I49: 91 | J49: 17 - 30 | K49: 2
B51: Giacomo Conterno - Cascina Francia | G51: 2007 | H51: 96+ | J51: 17 - 37 | K51: 2
B53: Giacomo Conterno - Vini Pregiati -Monforte D'Alba | G53: 1955 | K53: 1
B55: Giacomo Conterno - Vini Pregiati -Monforte D'Alba | G55: 1958 | K55: 1
B57: Giacomo Conterno | G57: 1964 | H57: 98 | K57: 1
B59: Bruno Giacosa - Collina Rionda di Serralunga D`Alba | G59: 1982 | H59: 98 | J59: 06 - 26 | K59: 1
B61: Bruno Giacosa - Collina Rionda di Serralunga D`Alba | G61: 1990 | H61: 92 | J61: 10 - 25 | K61: 2
B63: Bruno Giacosa - Falletto Di Serralunga D`Alba - Falletto | G63: 1985 | K63: 1
B65: Bruno Giacosa - Falletto Di Serralunga D`Alba - Falletto | G65: 1986 | H65: 97 | I65: 93 | J65: 05 - 25 | K65: 1
B67: BAROLO (continuação)
B69: Bruno Giacosa - Falletto Di Serralunga D`Alba - Falletto | G69: 1989 | H69: 97 | I69: 96 | J69: 10 - 30 | K69: 2
B71: Bruno Giacosa - Falletto Di Serralunga D`Alba - Falletto | G71: 1996 | H71: 98 | I71: 95 | J71: 11 - 31 | K71: 2
B73: Bruno Giacosa - Falletto Di Serralunga D'Alba - Falletto - Magnum | G73: 1996 | H73: 98 | I73: 95 | J73: 11 - 31 | K73: 1
B75: Bruno Giacosa - Falletto Di Serralunga D`Alba - Falletto | G75: 1999 | H75: 96 | J75: 06 - 35 | K75: 1
B77: Bruno Giacosa - Falletto Di Serralunga D`Alba - Falletto | G77: 2000 | H77: 96 | J77: 06 - 20 | K77: 2
B79: Bruno Giacosa - Falletto Di Serralunga D`Alba - Falletto | G79: 2001 | H79: 97 | I79: 97 | J79: 16 - 26 | K79: 2
...

Sheet B. It
C3: ADEGA RICARDO SENA
D6: VINHOS DA ITÁLIA
B7: BRANCO
B9: Vinho | G9: Safra | H9: R.P. | I9: W.S. | J9: Beber | K9: Estoque
J10: R.P.
B11: Francesco Gravner - Bianco Breg | G11: 2000 | I11: 92 | K11: 1
B13: Francesco Gravner - Bianco Breg | G13: 2004 | K13: 3
B15: Francesco Gravner - Bianco Breg | G15: 2005 | K15: 2
B17: Francesco Gravner - Ribolla | G17: 2000 | I17: 92 | K17: 3
B19: Francesco Gravner - Ribolla | G19: 2004 | K19: 1
B21: Francesco Gravner - Ribolla | G21: 2005 | K21: 1
B23: Francesco Gravner - Ribolla | G23: 2006 | K23: 2
B25: Trebbiano d'Abruzzo | G25: 2007 | K25: 1
B27: Trebbiano d'Abruzzo | G27: 2008 | K27: 2
B29: Trebbiano d'Abruzzo | G29: 2010 | K29: 1
B31: Langhe - Gaia & Rey - Gaja | G31: 2011 | K31: 1
B33: Langhe - Gaia & Rey - Gaja | G33: 2013 | H33: 93 | J33: 15 - 25 | K33: 1
B35: Langhe - Gaia & Rey - Gaja | G35: 2017 | H35: 93+ | J35: 19 - 30 | K35: 3
B37: Podversic Damijan - Ribolla Gialla | G37: 2010 | K37: 1
B39: Castello di Ama - Al Poggio | G39: 2016 | K39: 1
B41: Umbria - Marchesi Antinori - Bramito Della Sala - Chardonnay | G41: 2019 | H41: 96 | J41: 24 - 35 | K41: 2
B43: ITÁLIA ( total ) | K43: 26
L45: =SUM(K11:K42) -> 26

Sheet T. Es
C3: ADEGA RICARDO SENA
D6: VINHOS DA ESPANHA
B7: TINTO
B9: Vinho | G9: Safra | H9: R.P. | I9: W.S. | J9: Beber | K9: Estoque
J10: R.P.
B11: RIBERA DEL DUERO
B13: Vega - Sicilia "Único" Gran Reserva | G13: 1936 | K13: 1
B15: Vega - Sicilia "Único" Gran Reserva | G15: 1941 | K15: 1
B17: Vega - Sicilia "Único" Gran Reserva | G17: 1948 | H17: 86 | K17: 1
B19: Vega - Sicilia "Único" Gran Reserva | G19: 1953 | K19: 1
B21: Vega - Sicilia "Único" Gran Reserva | G21: 1957 | H21: 90 | J21: 13 - 17 | K21: 1
B23: Vega - Sicilia "Único" Gran Reserva | G23: 1958 | K23: 1
B25: Vega - Sicilia "Único" Gran Reserva | G25: 1960 | H25: 97 | J25: 70 - 30 | K25: 2
B27: Vega - Sicilia "Único" Gran Reserva | G27: 1962 | H27: 100 | J27: 12 - 20 | K27: 1
B29: Vega - Sicilia "Único" Gran Reserva | G29: 1964 | H29: 96 | J29: 12 - 25 | K29: 2
B31: Vega - Sicilia "Único" Gran Reserva | G31: 1965 | H31: 94 | J31: 12 - 20 | K31: 3
B33: Vega - Sicilia "Único" Gran Reserva - Magnum | G33: 1965 | H33: 94 | J33: 12 - 20 | K33: 1
B35: Vega - Sicilia "Único" Gran Reserva | G35: 1966 | H35: 95 | J35: 95 - 15 | K35: 1
B37: Vega - Sicilia "Único" Gran Reserva | G37: 1967 | H37: 96 | J37: 12 - 20 | K37: 5
B39: Vega - Sicilia "Único" Gran Reserva | G39: 1968 | H39: 98 | J39: 95 - 25 | K39: 2
B41: Vega - Sicilia "Único" Gran Reserva | G41: 1970 | H41: 100 | I41: 92 | J41: 90 - 50 | K41: 4
B43: Vega - Sicilia "Único" Gran Reserva - Magnum | G43: 1972 | H43: 89 | J43: 90 - 25 | K43: 1
B45: Vega - Sicilia "Único" Gran Reserva | G45: 1975 | H45: 95 | J45: 12 - 25 | K45: 2
B47: Vega - Sicilia "Único" Gran Reserva | G47: 1981 | H47: 96 | I47: 93 | J47: 12 - 30 | K47: 2
B49: Vega - Sicilia "Único" Gran Reserva | G49: 1982 | H49: 96 | I49: 91 | J49: 12 - 30 | K49: 1
B51: Vega - Sicilia "Único" Gran Reserva | G51: 1985 | H51: 93 | J51: 98 - 13 | K51: 1
B53: Vega - Sicilia "Único" Gran Reserva - Magnum | G53: 1987 | H53: 95 | J53: 14 - 30 | K53: 2
B55: Vega - Sicilia "Único" Gran Reserva | G55: 1987 | H55: 95 | J55: 14 - 30 | K55: 3
B57: Vega - Sicilia "Único" Gran Reserva | G57: 1989 | H57: 98 | I57: 90 | J57: 12 - 35 | K57: 3
B59: Vega - Sicilia "Único" Gran Reserva | G59: 1990 | H59: 93 | J59: 00 - 30 | K59: 3
B61: Vega - Sicilia "Único" Gran Reserva - Magnum | G61: 1991 | H61: 96 | I61: 91 | J61: 07 - 29 | K61: 1
B63: Vega - Sicilia "Único" Gran Reserva | G63: 1991 | H63: 96 | I63: 91 | J63: 07 - 29 | K63: 2
B65: Vega - Sicilia "Único" Gran Reserva | G65: 1994 | H65: 96 | I65: 96 | J65: 19 - 40 | K65: 6
B67: RIBERA DEL DUERO (continuação)
B69: Vega - Sicilia "Único" Gran Reserva | G69: 1995 | H69: 97 | I69: 94 | J69: 07 - 47 | K69: 4
B71: Vega - Sicilia "Único" Gran Reserva | G71: 1996 | H71: 97 | I71: 93 | J71: 18 - 50 | K71: 4
B73: Vega - Sicilia "Único" Gran Reserva | G73: 1998 | H73: 98 | I73: 91 | J73: 15 - 40 | K73: 5
B75: Vega - Sicilia "Único" Gran Reserva | G75: 1999 | H75: 92 | I75: 94 | J75: 16 - 30 | K75: 5
B77: Vega - Sicilia "Único" Gran Reserva | G77: 2000 | H77: 93 | I77: 92 | J77: 18 - 30 | K77: 3
B79: Vega - Sicilia "Único" Reserva Especial ( -- / -- / -- ) | K79: 1
...

Sheet B. Es
C3: ADEGA RICARDO SENA
D6: VINHOS DA ESPANHA
B7: BRANCO
B9: Vinho | G9: Safra | H9: R.P. | I9: W.S. | J9: Beber | K9: Estoque
J10: R.P.
B11: R. Lopes De Heredia - Vina Tondonia - Gran Reserva | G11: 1970 | H11: 93 | K11: 2
B13: R. Lopes De Heredia - Vina Tondonia - Gran Reserva | G13: 1976 | I13: 91 | K13: 1
B15: R. Lopes De Heredia - Vina Tondonia - Gran Reserva | G15: 1991 | H15: 93 | I15: 93 | K15: 1
B17: R. Lopes De Heredia - Vina Tondonia - Reserva | G17: 2003 | K17: 1
B19: R. Lopes De Heredia - Vina Tondonia - Reserva | G19: 2005 | H19: 95 | K19: 1
B21: R. Lopes De Heredia - Vina Tondonia - Reserva | G21: 2006 | H21: 95 | J21: 19 - 27 | K21: 2
B23: Marqués de Murrieta - Castillo Ygay - Gran Reserva | G23: 1986 | H23: 100 | K23: 1
B25: Bodegas Forjas Del Salnés - Rias Baixas - Leirana - Albariño | G25: 2009 | H25: 93 | K25: 4
B27: Priorat - Pedra de Guix - Terroir Al Límit Soc. Lda | G27: 2012 | H27: 94 | J27: 15 - 22 | K27: 1
B29: Priorat - Pedra de Guix - Terroir Al Límit Soc. Lda | G29: 2014 | H29: 94+ | J29: 16 - 22 | K29: 2
B31: Castilla y León - Raul Perez - El Castro de Valtuille - Godello | G31: 2018 | K31: 2
B35: ESPANHA ( total ) | K35: 18

Sheet T. Pt
C3: ADEGA RICARDO SENA
D6: VINHOS DE PORTUGAL
B7: TINTO
B9: Vinho | G9: Safra | H9: R.P. | I9: W.S. | J9: Beber | K9: Estoque
J10: R.P.
B11: DOURO
B13: Barca Velha - Casa Ferreirinha | G13: 1965 | K13: 1
B15: Barca Velha - Casa Ferreirinha | G15: 1981 | H15: 90 | K15: 1
B17: Barca Velha - Casa Ferreirinha | G17: 1982 | H17: 92 | K17: 1
B19: Barca Velha - Casa Ferreirinha | G19: 1983 | K19: 1
B21: Barca Velha - Casa Ferreirinha | G21: 1995 | I21: 89 | K21: 2
B23: Barca Velha - Casa Ferreirinha | G23: 1999 | H23: 94 | I23: 93 | J23: - 22 | K23: 1
B25: Barca Velha - Casa Ferreirinha | G25: 2000 | K25: 3
B27: Barca Velha - Casa Ferreirinha | G27: 2004 | K27: 2
B29: Barca Velha - Casa Ferreirinha | G29: 2011 | H29: 97 | J29: 22 - 40 | K29: 2
B31: Casa Ferreirinha - Reserva | G31: 1989 | H31: 92 | I31: 87 | J31: - 11 | K31: 1
B33: Casa Ferreirinha - Reserva | G33: 1994 | H33: 93 | I33: 91 | J33: - 15 | K33: 1
B35: Casa Ferreirinha - Reserva | G35: 1996 | H35: 89 | I35: 91 | J35: - 21 | K35: 1
B37: Casa Ferreirinha - Reserva Especial | G37: 1962 | K37: 1
B39: Casa Ferreirinha - Reserva Especial | G39: 1997 | H39: 95 | K39: 1
B41: Quinta da Leda - Casa Ferreirinha | G41: 2004 | H41: 90 | I41: 90 | J41: - 17 | K41: 1
B43: Quinta da Leda - Casa Ferreirinha | G43: 2007 | H43: 92 | I43: 92 | K43: 1
B45: Quinta da Leda - Casa Ferreirinha | G45: 2008 | I45: 91 | K45: 2
B47: Quinta do Crasto - Vinha Maria Teresa | G47: 2003 | H47: 94 | J47: 15 - 25 | K47: 3
B49: Quinta do Crasto - Vinha Maria Teresa | G49: 2005 | H49: 94 | J49: 15 - 30 | K49: 3
B51: Quinta do Crasto - Touriga Nacional | G51: 2005 | H51: 91 | I51: 94 | J51: 09 - 20 | K51: 1
B53: Quinta do Crasto - Vinhas Velhas | G53: 2005 | H53: 91 | I53: 95 | J53: - 19 | K53: 1
B55: Quinta do Crasto - Vinhas Velhas | G55: 2022 | K55: 4
B57: Fojo | G57: 2000 | H57: 95 | I57: 94 | J57: - 20 | K57: 1
B59: Chryseia | G59: 2001 | H59: 90 | K59: 1
B61: Chryseia | G61: 2005 | H61: 92 | I61: 88 | J61: - 20 | K61: 1
B63: Chryseia | G63: 2006 | H63: 89 | K63: 1
B65: Quinta do Vale Meão | G65: 1999 | K65: 2
B67: DOURO (continuação)
B69: Quinta do Vale Meão | G69: 2000 | H69: 91 | K69: 2
B71: Quinta do Vale Meão | G71: 2001 | H71: 91 | I71: 93 | J71: now -17 | K71: 1
B73: Quinta do Vale Meão | G73: 2011 | H73: 96 | K73: 3
B75: Quinta do Vale Meão | G75: 2015 | H75: 91+ | K75: 3
B77: Quinta do Noval - Vinhas da Marka | G77: 2019 | K77: 1
B79: Quinta do Noval - Vinhas do Passadouro | G79: 2020 | H79: 93 | J79: 24 - 32 | K79: 1
...

Sheet B. Pt
C3: ADEGA RICARDO SENA
D6: VINHOS DE PORTUGAL
B7: BRANCO
B9: Vinho | G9: Safra | H9: R.P. | I9: W.S. | J9: Beber | K9: Estoque
J10: R.P.
B11: PORTUGAL
B13: Lisboa - Colares Manoel José Colares | G13: 1947 | K13: 1
B15: Lisboa - Colares Manoel José Colares | G15: 1957 | K15: 1
B17: Lisboa - Colares Manoel José Colares | G17: 1962 | K17: 1
B19: Lisboa - Colares Chitas - Reserva Branco | G19: 1979 | K19: 1
B21: Lisboa - Colares - Monte Cascas - Malvasia | G21: 2013 | K21: 1
B23: Lisboa - Colares - Ramilo - Malvasia | G23: 2020 | K23: 3
B25: Lisboa - Quinta do Monte d`Oiro - Magnum | G25: 2012 | K25: 2
B27: Alvarinho -Quinta de Soalheiro - Soalheiro | G27: 2015 | H27: 94 | J27: 16 - 30 | K27: 1
B29: Dão - Casa da Passarella - Villa Oliveira - Encruzado | G29: 2011 | H29: 91 | J29: 14 - 18 | K29: 1
B31: Dão - Casa da Passarella - Villa Oliveira - Encruzado | G31: 2014 | H31: 91 | J31: 18 - 24 | K31: 2
B33: Dão - Quinta da Pellada - Primus | G33: 2017 | K33: 3
B35: Dão - Quinta da Pellada - Primus | G35: 2022 | H35: 95 | J35: 24 - 32 | K35: 1
B37: Dão - Quinta da Pellada - Quinta de Saes - Reserva Encruzado | G37: 2018 | H37: 90 | J37: 18 - 32 | K37: 4
B39: Dão - Domínio do Açor - Branco | G39: 2021 | H39: 91 | J39: 23 - 27 | K39: 3
B41: Dão - Domínio do Açor - Bical - Vinha Celta | G41: 2021 | H41: 92 | J41: 23 - 30 | K41: 1
B43: Dão - Domínio do Açor - Bical - Vinha Celta | G43: 2022 | H43: 95 | J43: 24 - 30 | K43: 3
B45: Dão - Domínio do Açor - Bical - Vinha Celta - Magnum | G45: 2022 | H45: 95 | J45: 24 - 30 | K45: 1
B47: Dão - Domínio do Açor - Bical - Vinha Celta | G47: 2023 | K47: 5
B49: Dão - Domínio do Açor - Vinha Ruina - Cerceal Branco - Magnum | G49: 2022 | H49: 94 | J49: 24 - 30 | K49: 1
B51: Dão - Domínio do Açor - Vinha Ruina - Cerceal Branco | G51: 2023 | K51: 5
B53: Dão - Domínio do Açor - Encruzado | G53: 2021 | H53: 92 | J53: 23 - 28 | K53: 1
B55: Dão - Domínio do Açor - Encruzado | G55: 2022 | H55: 94 | J55: 24 - 29 | K55: 1
B57: Dão - Domínio do Açor - Encruzado - Magnum | G57: 2022 | H57: 94 | J57: 24 - 29 | K57: 1
B59: Dão - Domínio do Açor - Encruzado | G59: 2023 | K59: 5
B61: Dão - Domínio do Açor - Vila Romana | G61: 2022 | K61: 3
B63: Dão - Domínio do Açor - Vila Romana - Não tinha espaço na adega de branco | G63: 2023 | K63: 15
B65: Dão - Domínio do Açor - Vila Romana - Magnum | G65: 2023 | K65: 1
B67: PORTUGAL (continuação)
B69: Dão - Luís Seabra - Granito Cru | G69: 2021 | H69: 92 | J69: 24 - 30 | K69: 3
B71: Douro - Jorge Nobre Moreira - Poeira | G71: 2013 | K71: 1
B73: Douro - Jorge Nobre Moreira - La Rosa - Reserva | G73: 2018 | K73: 3
B75: Douro - Jorge Nobre Moreira - Pó de Poeira | G75: 2019 | H75: 90 | J75: 20 - 27 | K75: 2
B77: Douro - Wine & Soul - Guru | G77: 2019 | H77: 95 | J77: 20 - 34 | K77: 3
B79: Douro - Wine & Soul - Guru | G79: 2022 | H79: 94 | J79: 24 - 34 | K79: 2
...

Sheet T. US
C3: ADEGA RICARDO SENA
D6: VINHOS DOS ESTADOS UNIDOS
B7: TINTO
B9: Vinho | G9: Safra | H9: R.P. | I9: W.S. | J9: Beber | K9: Estoque
J10: R.P.
B11: Heitz Cellar - Napa Valley-C. S. | G11: 1970 | K11: 1
B13: Heitz Cellar - Napa Valley-C. S. | G13: 1974 | H13: 98 | J13: 94 - 19 | K13: 1
B15: Heitz Cellar - Napa Valley-C. S. - Magnum | G15: 1978 | H15: 92 | J15: 87 - 30 | K15: 1
B17: Heitz Cellar - Napa Valley-C. S. | G17: 1984 | H17: 92 | K17: 1
B19: Heitz Cellar - Napa Valley-C. S. - Magnum | G19: 1984 | H19: 92 | K19: 2
B21: Heitz Cellar - Napa Valley-C. S. | G21: 1985 | H21: 94 | J21: 95 - 15 | K21: 1
B23: Heitz Cellar - Napa Valley-C. S. | G23: 1997 | H23: 90 | J23: 02 - 17 | K23: 1
B25: Heitz Cellar - Napa Valley-C. S. | G25: 2001 | H25: 95+ | I25: 93 | J25: 16 - 35 | K25: 3
B27: Diamond Creek - Volcanic Hill - C.S. | G27: 1979 | K27: 2
B29: Diamond Creek - Volcanic Hill - C.S. | G29: 1981 | K29: 1
B31: Diamond Creek - Volcanic Hill - C.S. - Magnum | G31: 2004 | H31: 96 | J31: 14 - 34 | K31: 1
B33: Dalla Valle Maya - Napa Valley - C.S. / C.F. | G33: 1988 | H33: 93 | J33: 93 - 18 | K33: 1
B35: Dalla Valle Maya - Napa Valley - C.S. / C.F. | G35: 1989 | H35: 89 | K35: 1
B37: Dalla Valle Maya - Napa Valley - C.S. / C.F. | G37: 1990 | H37: 96 | I37: 97 | K37: 1
B39: Dalla Valle Maya - Napa Valley - C.S. / C.F. | G39: 1991 | H39: 99 | I39: 95 | J39: 98 - 19 | K39: 1
B41: Dalla Valle Maya - Napa Valley - C.S. / C.F. | G41: 1992 | H41: 100 | I41: 92 | J41: 99 - 19 | K41: 2
B43: Dalla Valle Maya - Napa Valley - C.S. / C.F. | G43: 1993 | H43: 98 | I43: 93 | J43: 01 - 25 | K43: 3
B45: Dalla Valle Maya - Napa Valley - C.S. / C.F. | G45: 1994 | H45: 99 | J45: 97 - 27 | K45: 1
B47: Dalla Valle Maya - Napa Valley - C.S. / C.F. | G47: 1995 | H47: 96 - 98 | I47: 95 | K47: 1
B49: Dalla Valle Maya - Napa Valley - C.S. / C.F. | G49: 1997 | H49: 99 | J49: 05 - 30 | K49: 2
B51: Dalla Valle Maya - Napa Valley - C.S. / C.F. | G51: 2001 | H51: 98 | I51: 88 | J51: 15 - 55 | K51: 3
B53: Dalla Valle Maya - Napa Valley - C.S. / C.F. | G53: 2002 | H53: 100 | I53: 89 | J53: 18 - 40 | K53: 3
B55: Dalla Valle Maya - Napa Valley - C.S. / C.F. | G55: 2009 | H55: 99 | K55: 1
B57: Dalla Valle - Napa Valley - C.S. | G57: 1996 | H57: 96 | J57: 01 - 25 | K57: 2
B59: Paul Hobbs - Carneros - Napa Valley - C. S. | G59: 1992 | I59: 93 | K59: 1
B61: Paul Hobbs - Beckstoffer To Kalon - C. S. | G61: 2002 | H61: 100 | I61: 94 | J61: 22 - 50 | K61: 2
B63: Paul Hobbs - Beckstoffer To Kalon - C. S. | G63: 2005 | H63: 95 | I63: 95 | J63: 07 - 37 | K63: 1
B65: Paul Hobbs - Beckstoffer Dr Crane - C.S. | G65: 2005 | H65: 95+ | I65: 97 | J65: 07 - 27 | K65: 1
B67: Araujo - Eisele Vineyard - C.S. | G67: 1992 | H67: 94 - 96 | J67: 00 - 20 | K67: 3
B69: Araujo - Eisele Vineyard - C.S. | G69: 1993 | H69: 96 | I69: 94 | J69: 96 - 21 | K69: 4
B71: Araujo - Eisele Vineyard - C.S. | G71: 1994 | H71: 95 | J71: 97 - 17 | K71: 3
B73: Araujo - Eisele Vineyard - C.S. - Magnum | G73: 1994 | H73: 95 | J73: 97 - 17 | K73: 2
B75: Araujo - Eisele Vineyard - C.S. - Magnum | G75: 1995 | H75: 98 | I75: 94 | J75: 01 - 30 | K75: 1
B77: Araujo - Eisele Vineyard - C.S. | G77: 1995 | H77: 98 | I77: 94 | J77: 01 - 30 | K77: 4
B79: Araujo - Eisele Vineyard - C.S. | G79: 1996 | H79: 94 | I79: 94 | J79: 05 - 25 | K79: 1
...

Sheet B. US
C3: ADEGA RICARDO SENA
D6: VINHOS DOS ESTADOS UNIDOS
B7: BRANCO
B9: Vinho | G9: Safra | H9: R.P. | I9: W.S. | J9: Beber | K9: Estoque
J10: R.P.
B11: Marcassin - Hudson Ranch - Carneros E Block | G11: 1995 | H11: 97 | I11: 96 | K11: 1
B13: Marcassin Three sisters Sonoma Coast Chardonnay | G13: 2001 | H13: 95 | I13: 98 | K13: 1
B15: Marcassin Three sisters Sonoma Coast Chardonnay | G15: 2002 | H15: 95 | I15: 97 | K15: 2
B17: Marcassin Three sisters Sonoma Coast Chardonnay | G17: 2003 | H17: 97 | I17: 93 | K17: 1
B19: Marcassin Three sisters Sonoma Coast Chardonnay | G19: 2006 | H19: 96 | I19: 96 | K19: 2
B21: Marcassin Three sisters Sonoma Coast Chardonnay | G21: 2007 | H21: 96+ | I21: 95 | K21: 1
B23: Marcassin - Gauer Vineyard - Alexander Valley - Chardonnay | G23: 1994 | K23: 1
B25: Marcassin - Gauer Vineyard - Alexander Valley - Chardonnay | G25: 1995 | K25: 1
B27: Marcassin - Alexander Mountain Upper Barn - Alexander Valley - Chardonnay | G27: 2000 | H27: 90 | K27: 1
B29: Kistler - Sonoma Chardonnay | G29: 1992 | H29: 95 | K29: 3
B31: Kistler - Sonoma Chardonnay | G31: 1994 | H31: 96 | K31: 3
B33: Kistler - Sonoma Chardonnay | G33: 1995 | H33: 94 | K33: 1
B35: Kistler - Sonoma Chardonnay Cuvee Cathleen | G35: 1994 | H35: 96 | I35: 93 | K35: 2
B37: Kistler - Sonoma Chardonnay Cuvee Cathleen | G37: 1997 | H37: 96 | I37: 92 | K37: 2
B39: Kistler - Sonoma Chardonnay Cuvee Cathleen | G39: 1998 | H39: 95 - 96 | K39: 2
B41: Kistler - Sonoma Chardonnay Cuvee Cathleen | G41: 1999 | H41: 97 | J41: 02 - 10 | K41: 1
B43: Kistler - Sonoma Chardonnay Cuvee Cathleen | G43: 2003 | H43: 98 - 100 | K43: 2
B45: Kistler - Sonoma Chardonnay Cuvee Cathleen | G45: 2006 | H45: 98 | K45: 1
B47: Kistler - Sonoma Chardonnay Cuvee Cathleen | G47: 2007 | H47: 97 | K47: 1
B49: Kistler - Carneros - Hudson Vineyard - Chardonnay | G49: 2009 | H49: 96+ | K49: 1
B51: Kistler - Carneros - Hudson Vineyard - Chardonnay | G51: 2013 | H51: 91 | J51: 16 - 22 | K51: 1
B53: Kistler - Sonoma Coast - Durell Vineyard - Chardonnay | G53: 2012 | H53: 94 | K53: 1
B55: Kistler - Sonoma Coast - Dutton Ranch - Chardonnay | G55: 2011 | H55: 93 | K55: 1
B57: Kistler - Sonoma Coast - Les Noisetiers - Chardonnay | G57: 2020 | K57: 3
B59: Kistler - Sonoma Coast - Les Noisetiers - Chardonnay | G59: 2021 | K59: 4
B61: Kistler - Stone Flat - Sonoma Coast - Chardonnay | G61: 2012 | H61: 92 | K61: 1
B63: Kistler - Trenton Road House - Sonoma Coast - Chardonnay | G63: 2009 | H63: 96 | K63: 1
B65: Kistler - Russian River Valley - Vine Hill Vineyard | G65: 1994 | H65: 93 | K65: 1
B67: Kistler - Russian River Valley - Vine Hill Vineyard | G67: 2001 | H67: 95 | K67: 1
B69: Kistler - Russian River Valley - Vine Hill Vineyard | G69: 2002 | H69: 92 - 95 | K69: 1
B71: Kistler - Russian River Valley - Vine Hill Vineyard | G71: 2012 | H71: 95 | J71: 15 - 22 | K71: 1
B73: Kistler - Russian River Valley - Dutton Ranch - Chardonnay | G73: 2000 | H73: 91 | K73: 1
B75: Kistler - Russian River Valley - Dutton Ranch - Chardonnay | G75: 2013 | H75: 94 | J75: 16 - 22 | K75: 1
B77: Peter Michael - Clos Dú Ciel - Magnum | G77: 1996 | H77: 93 | K77: 1
B79: Peter Michael - Cuvée Indigène | G79: 1995 | H79: 95 | K79: 1
...

Sheet T. Aust
C3: ADEGA RICARDO SENA
D6: VINHOS DA AUSTRÁLIA
B7: TINTO
B9: Vinho | G9: Safra | H9: R.P. | I9: W.S. | J9: Beber | K9: Estoque
J10: R.P.
B11: Grange Hermitage - Penfolds - Barossa Valley - Shiraz | G11: 1966 | H11: 93 | J11: 02 - 12 | K11: 2
B13: Grange Hermitage - Penfolds - Barossa Valley - Shiraz | G13: 1967 | H13: 90 | I13: 91 | J13: - 02 | K13: 1
B15: Grange Hermitage - Penfolds - Barossa Valley - Shiraz | G15: 1971 | H15: 96 | I15: 92 | J15: - 12 | K15: 1
B17: Grange Hermitage - Penfolds - Barossa Valley - Shiraz | G17: 1973 | H17: 90 | I17: 87 | J17: 02 - 09 | K17: 2
B19: Grange Hermitage - Penfolds - Barossa Valley - Shiraz | G19: 1975 | H19: 92 | J19: 00 - 17 | K19: 3
B21: Grange Hermitage - Penfolds - Barossa Valley - Shiraz | G21: 1977 | H21: 93 | J21: 00 - 18 | K21: 3
B23: Grange Hermitage - Penfolds - Barossa Valley - Shiraz | G23: 1980 | H23: 94+ | K23: 1
B25: Grange Hermitage - Penfolds - Barossa Valley - Shiraz | G25: 1981 | H25: 97 | I25: 89 | J25: 05 - 25 | K25: 5
B27: Grange Hermitage - Penfolds - Barossa Valley - Shiraz | G27: 1982 | H27: 97 | I27: 92 | J27: 02 - 16 | K27: 3
B29: Grange Hermitage - Penfolds - Barossa Valley - Shiraz | G29: 1984 | H29: 94 | K29: 2
B31: Grange Hermitage - Penfolds - Barossa Valley - Shiraz | G31: 1986 | H31: 98+ | I31: 98 | J31: 09 - 39 | K31: 6
B33: Grange - Penfolds - Barossa Valley - Shiraz | G33: 1990 | H33: 95 | J33: 12 - 20 | K33: 1
B35: Grange - Penfolds - Barossa Valley - Shiraz | G35: 1991 | H35: 93 | I35: 95 | J35: 02 - 17 | K35: 1
B37: Grange - Penfolds - Barossa Valley - Shiraz | G37: 1997 | H37: 94 | K37: 1
B39: Grange - Penfolds - Barossa Valley - Shiraz | G39: 1998 | H39: 98+ | I39: 97 | J39: 09 - 39 | K39: 5
B41: Grange - Penfolds - Barossa Valley - Shiraz | G41: 1999 | H41: 92 | I41: 94 | J41: 06 - 19 | K41: 5
B43: Grange - Penfolds - Barossa Valley - Shiraz | G43: 2001 | H43: 98+ | I43: 93 | J43: 10 - 30 | K43: 2
B45: Grange - Penfolds - Barossa Valley - Shiraz | G45: 2002 | H45: 98 | I45: 95 | J45: 07 - 50 | K45: 2
B47: Grange - Penfolds - Barossa Valley - Shiraz | G47: 2003 | H47: 92 | I47: 94 | J47: 14 - 30 | K47: 1
B49: Grange - Penfolds - Barossa Valley - Shiraz | G49: 2004 | H49: 99 | I49: 98 | J49: 16 - 50 | K49: 4
B51: Grange - Penfolds - Barossa Valley - Shiraz | G51: 2005 | H51: 97 | J51: 13 - 25 | K51: 1
B53: Bin 95 - Penfolds - Barossa Valley - C. S. | G53: 1981 | K53: 1
B55: Bin 95 - Penfolds - Barossa Valley - Shiraz | G55: 1985 | K55: 1
B57: Bin 95 - Penfolds - Barossa Valley - C. S. | G57: 2009 | K57: 1
B59: Bin 707 - Penfolds - Barossa Valley - C. S. | G59: 1986 | K59: 1
B61: Bin 707 - Penfolds - Barossa Valley - C. S. | G61: 1998 | H61: 90 | K61: 1
B63: Bin 707 - Penfolds - Barossa Valley - C. S. | G63: 2005 | H63: 94 | J63: 09 - 34 | K63: 1
B65: Block 42 - Penfolds - Barossa Valley - Kalimna C. S. | G65: 1996 | K65: 1
B67: Henschke Hill Of Grace - Henschke - Shiraz | G67: 1987 | H67: 93 | K67: 4
B69: Henschke Hill Of Grace - Henschke - Shiraz - Magnum | G69: 1987 | H69: 93 | K69: 1
B71: Henschke Hill Of Grace - Henschke - Shiraz | G71: 1989 | H71: 94 | K71: 2
B73: Henschke Hill Of Grace - Henschke - Shiraz | G73: 1990 | H73: 97 | J73: 13 - 25 | K73: 4
B75: Henschke Hill Of Grace - Henschke - Shiraz | G75: 1991 | H75: 97 | I75: 91 | J75: 10 - 25 | K75: 4
B77: Henschke Hill Of Grace - Henschke - Shiraz | G77: 1994 | H77: 98 | I77: 95 | J77: 13 - 30 | K77: 4
B79: Henschke Hill Of Grace - Henschke - Shiraz | G79: 1996 | H79: 92 | I79: 98 | J79: 10 - 30 | K79: 2
...
